<robot name="rrp_robot"> 

  <!-- Materiales -->
  <material name="red">
    <color rgba="1 0 0 1"/>
  </material>
  <material name="green">
    <color rgba="0 1 0 1"/>
  </material>
  <material name="blue">
    <color rgba="0 0 1 1"/>
  </material>
  <material name="yellow">
    <color rgba="1 1 0 1"/>
  </material>
  <material name="magenta">
    <color rgba="1 0 1 1"/>
  </material>
  <material name="cyan">
    <color rgba="0 1 1 1"/>
  </material>
  <material name="black">
    <color rgba="0 0 0 1"/>
  </material>

  <!-- Definición de eslabones --> 
  <link name="world_link"/>
  
  <link name="base_link">
    <visual>
      <origin xyz="0 0 0.05" rpy="1.57 0 0"/> 
      <geometry> 
        <box size="0.2 0.1 0.2"/> 
      </geometry> 
      <material name="black"/> 
    </visual> 
  </link> 
  
  <link name="x_axis"> 
    <visual> 
      <origin xyz="0 0 0" rpy="0 0 0"/> 
      <geometry> 
        <box size="0.4 0.05 0.05"/> 
      </geometry> 
      <material name="red"/> 
    </visual> 
  </link> 
  
  <link name="y_axis"> 
    <visual> 
      <origin xyz="0 0 0" rpy="0 0 0"/> 
      <geometry> 
        <box size="0.05 0.4 0.05"/> 
      </geometry> 
      <material name="green"/> 
    </visual> 
  </link> 
  
  <link name="z_axis"> 
    <visual> 
      <origin xyz="0 0 0" rpy="0 0 0"/> 
      <geometry> 
        <box size="0.05 0.05 0.2"/> 
      </geometry> 
      <material name="blue"/> 
    </visual> 
  </link> 

  <link name="shoulder_link"> 
    <visual> 
      <origin xyz="0 0 0.15" rpy="0 0 0"/> 
      <geometry> 
        <cylinder radius="0.05" length="0.3"/>
      </geometry> 
      <material name="magenta"/> 
    </visual> 
  </link> 

  <link name="arm_link"> 
    <visual> 
      <origin xyz="0.15 0 0" rpy="0 0 0"/> 
      <geometry> 
        <box size="0.3 0.06 0.06"/> 
      </geometry> 
      <material name="yellow"/> 
    </visual> 
  </link> 
  
  <link name="forearm_link"> 
    <visual> 
      <origin xyz="0 0 0.10" rpy="0 0 0"/> 
      <geometry> 
        <box size="0.04 0.04 0.3"/> 
      </geometry> 
      <material name="cyan"/> 
    </visual> 
  </link> 

  <link name="end_arm_link"> 
    <visual> 
      <origin xyz="0 0 0.15" rpy="0 0 0"/> 
      <geometry> 
        <box size="0.2 0.05 0.05"/> 
      </geometry> 
      <material name="red"/> 
    </visual> 
  </link>

  <!-- Definición de juntas --> 
  <joint name="world_joint" type="fixed"> 
    <parent link="world_link"/> 
    <child link="base_link"/> 
    <origin xyz="0 0 0" rpy="0 0 0"/> 
  </joint>

  <joint name="shoulder_joint" type="revolute"> 
    <parent link="base_link"/> 
    <child link="shoulder_link"/> 
    <origin xyz="0 0 0.1" rpy="0 0 0"/> 
    <axis xyz="0 0 1"/> 
    <limit lower="-2.8" upper="2.8" effort="10" velocity="1"/>
  </joint>

  <joint name="x_joint" type="fixed"> 
    <parent link="base_link"/> 
    <child link="x_axis"/> 
    <origin xyz="0.2 0 0" rpy="0 0 0"/> 
  </joint>

  <joint name="y_joint" type="fixed"> 
    <parent link="base_link"/> 
    <child link="y_axis"/> 
    <origin xyz="0 0.2 0" rpy="0 0 0"/> 
  </joint>

  <joint name="z_joint" type="fixed"> 
    <parent link="base_link"/> 
    <child link="z_axis"/> 
    <origin xyz="0 0 0.2" rpy="0 0 0"/> 
  </joint>

  <joint name="arm_joint" type="fixed"> 
    <parent link="shoulder_link"/> 
    <child link="arm_link"/> 
    <origin xyz="0 0 0.3" rpy="0 0 0"/> 
  </joint>

  <joint name="forearm_joint" type="revolute"> 
    <parent link="arm_link"/> 
    <child link="forearm_link"/> 
    <origin xyz="0.3 0 0.05" rpy="0 1.57 0"/> 
    <axis xyz="1 0 0"/>
    <limit lower="-2.5" upper="2.5" effort="10" velocity="1"/>
  </joint>

  <joint name="end_arm_joint" type="prismatic"> 
    <parent link="forearm_link"/> 
    <child link="end_arm_link"/> 
    <origin xyz="0.1 0 0.05" rpy="0 0 0"/> 
    <axis xyz="1 0 0"/>
    <limit lower="0" upper="0.25" effort="10" velocity="1"/>
  </joint>

</robot>
